python3 test/test.py


LOGGERS BEFORE
[<_StderrHandler <stderr> (WARNING)>]
LOGGERS AFTER
[<_StderrHandler <stderr> (WARNING)>]
Traceback (most recent call last):
  File "test/test.py", line 17, in <module>
    shallow(bar, [31m15[m)
    [36m|       -> 2[m
    [36m-> <function shallow at 0xDEADBEEF>[m
  File "test/test.py", line 8, in shallow
    deep(a + b)
    [36m|    |   -> 15[m
    [36m|    -> 2[m
    [36m-> <function deep at 0xDEADBEEF>[m
  File "test/test.py", line 13, in deep
    [33;1massert[m val > [31m10[m and foo == [31m60[m
    [36m       |            -> 52[m
    [36m       -> 17[m
AssertionError: [33;1massert[m val > [31m10[m and foo == [31m60[m



python3 test/test_color.py


True



python3 test/test_encoding.py


LOGGERS BEFORE
[<_StderrHandler <stderr> (WARNING)>]
LOGGERS AFTER
[<_StderrHandler <stderr> (WARNING)>]
Traceback (most recent call last):
  File "test/test_encoding.py", line 14, in <module>
    div()
    [36m-> <function div at 0xDEADBEEF>[m
  File "test/test_encoding.py", line 11, in div
    [33;1mreturn[m _deep([31m'å¤©'[m)
    [36m       -> <function _deep at 0xDEADBEEF>[m
  File "test/test_encoding.py", line 8, in _deep
    [33;1mreturn[m [31m1[m / val
    [36m           -> 'å¤©'[m
TypeError: unsupported operand type(s) for /: 'int' and 'str'



./test/test_interactive.sh


spawn python3 -m better_exceptions -q
sh: warning: setlocale: LC_ALL: cannot change locale (en_US.ascii)
LOGGERS BEFORE
[<_StderrHandler <stderr> (WARNING)>]
LOGGERS AFTER
[<_StderrHandler <stderr> (WARNING)>]
>>> import better_exceptions
>>> def foo(a):
...     assert a > 10
... 
>>> foo(1)
Traceback (most recent call last):
  File "<console>", line 1, in <module>
    foo([31m1[m)
    [36m-> <function foo at 0xDEADBEEF>[m
  File "<console>", line 2, in foo
    [33;1massert[m a > [31m10[m
    [36m       -> 1[m
AssertionError: [33;1massert[m a > [31m10[m
>>> exit()



./test/test_string.sh



import better_exceptions; better_exceptions.hook(); a = 5; assert a > 10 # this should work fine

/bin/sh: warning: setlocale: LC_ALL: cannot change locale (en_US.ascii)
Traceback (most recent call last):
  File "<string>", line 1, in <module>
    [33;1mimport[m better_exceptions; better_exceptions.hook(); a = [31m5[m; [33;1massert[m a > [31m10[m [2;37m# this should work fine[m
    [36m                          |                         |             -> 5[m
    [36m                          |                         -> 5[m
    [36m                          -> <module 'test_module' from '/removed/for/test/purposes.py'>[m
AssertionError: [33;1mimport[m better_exceptions; better_exceptions.hook(); a = [31m5[m; [33;1massert[m a > [31m10[m [2;37m# this should work fine[m
LOGGERS BEFORE
[<_StderrHandler <stderr> (WARNING)>]
LOGGERS AFTER
[<_StderrHandler <stderr> (WARNING)>]

/bin/sh: warning: setlocale: LC_ALL: cannot change locale (en_US.ascii)
Traceback (most recent call last):
  File "<string>", line 1, in <module>
    [33;1mimport[m better_exceptions; better_exceptions.hook(); a = [31m5[m; [33;1massert[m a > [31m10[m [2;37m# this should work fine[m
    [36m                          |                         |             -> 5[m
    [36m                          |                         -> 5[m
    [36m                          -> <module 'test_module' from '/removed/for/test/purposes.py'>[m
AssertionError: [33;1mimport[m better_exceptions; better_exceptions.hook(); a = [31m5[m; [33;1massert[m a > [31m10[m [2;37m# this should work fine[m
LOGGERS BEFORE
[<_StderrHandler <stderr> (WARNING)>]
LOGGERS AFTER
[<_StderrHandler <stderr> (WARNING)>]

from __future__ import print_function; import better_exceptions; better_exceptions.hook(); a = "why hello there"; print(a); assert False

/bin/sh: warning: setlocale: LC_ALL: cannot change locale (en_US.ascii)
Traceback (most recent call last):
  File "<string>", line 1, in <module>
    from __future__ import print_function; [33;1mimport[m better_exceptions; better_exceptions.hook(); a = [31m'why hello there'[m; [35;1mprint[m(a); [33;1massert[m False
    [36m                                                                 |                         |                            -> 'why hello there'[m
    [36m                                                                 |                         -> 'why hello there'[m
    [36m                                                                 -> <module 'test_module' from '/removed/for/test/purposes.py'>[m
AssertionError: from __future__ import print_function; [33;1mimport[m better_exceptions; better_exceptions.hook(); a = [31m'why hello there'[m; [35;1mprint[m(a); [33;1massert[m False
LOGGERS BEFORE
[<_StderrHandler <stderr> (WARNING)>]
LOGGERS AFTER
[<_StderrHandler <stderr> (WARNING)>]
why hello there

/bin/sh: warning: setlocale: LC_ALL: cannot change locale (en_US.ascii)
Traceback (most recent call last):
  File "<string>", line 1, in <module>
    from __future__ import print_function; [33;1mimport[m better_exceptions; better_exceptions.hook(); a = [31m'why hello there'[m; [35;1mprint[m(a); [33;1massert[m False
    [36m                                                                 |                         |                            -> 'why hello there'[m
    [36m                                                                 |                         -> 'why hello there'[m
    [36m                                                                 -> <module 'test_module' from '/removed/for/test/purposes.py'>[m
AssertionError: from __future__ import print_function; [33;1mimport[m better_exceptions; better_exceptions.hook(); a = [31m'why hello there'[m; [35;1mprint[m(a); [33;1massert[m False
LOGGERS BEFORE
[<_StderrHandler <stderr> (WARNING)>]
LOGGERS AFTER
[<_StderrHandler <stderr> (WARNING)>]
why hello there

from __future__ import print_function; import better_exceptions; better_exceptions.hook(); a = "why     hello          " + "   there"; print(a); assert False

/bin/sh: warning: setlocale: LC_ALL: cannot change locale (en_US.ascii)
Traceback (most recent call last):
  File "<string>", line 1, in <module>
    from __future__ import print_function; [33;1mimport[m better_exceptions; better_exceptions.hook(); a = [31m'why     hello          '[m + [31m'   there'[m; [35;1mprint[m(a); [33;1massert[m False
    [36m                                                                 |                         |                                                 -> 'why     hello             there'[m
    [36m                                                                 |                         -> 'why     hello             there'[m
    [36m                                                                 -> <module 'test_module' from '/removed/for/test/purposes.py'>[m
AssertionError: from __future__ import print_function; [33;1mimport[m better_exceptions; better_exceptions.hook(); a = [31m'why     hello          '[m + [31m'   there'[m; [35;1mprint[m(a); [33;1massert[m False
LOGGERS BEFORE
[<_StderrHandler <stderr> (WARNING)>]
LOGGERS AFTER
[<_StderrHandler <stderr> (WARNING)>]
why     hello             there

/bin/sh: warning: setlocale: LC_ALL: cannot change locale (en_US.ascii)
Traceback (most recent call last):
  File "<string>", line 1, in <module>
    from __future__ import print_function; [33;1mimport[m better_exceptions; better_exceptions.hook(); a = [31m'why     hello          '[m + [31m'   there'[m; [35;1mprint[m(a); [33;1massert[m False
    [36m                                                                 |                         |                                                 -> 'why     hello             there'[m
    [36m                                                                 |                         -> 'why     hello             there'[m
    [36m                                                                 -> <module 'test_module' from '/removed/for/test/purposes.py'>[m
AssertionError: from __future__ import print_function; [33;1mimport[m better_exceptions; better_exceptions.hook(); a = [31m'why     hello          '[m + [31m'   there'[m; [35;1mprint[m(a); [33;1massert[m False
LOGGERS BEFORE
[<_StderrHandler <stderr> (WARNING)>]
LOGGERS AFTER
[<_StderrHandler <stderr> (WARNING)>]
why     hello             there



python3 test/test_logging.py


ERROR:__main__:callback failed
Traceback (most recent call last):
  File "test/test_logging.py", line 16, in foo
    cb()
    [36m-> <function bar3 at 0xDEADBEEF>[m
  File "test/test_logging.py", line 33, in bar3
    [33;1mraise[m [35;1mException[m([31m'this is a test exception'[m)
Exception: this is a test exception

ERROR:__main__:callback failed
Traceback (most recent call last):
  File "test/test_logging.py", line 16, in foo
    cb()
    [36m-> <function bar4 at 0xDEADBEEF>[m
  File "test/test_logging.py", line 38, in bar4
    [33;1massert[m baz == [31m90[m
    [36m       -> 52[m
AssertionError: [33;1massert[m baz == [31m90[m

LOGGERS BEFORE
[<_StderrHandler <stderr> (WARNING)>]
LOGGERS AFTER
[<_StderrHandler <stderr> (WARNING)>]
LOGGERS BEFORE
[<_StderrHandler <stderr> (WARNING)>, <StreamHandler <stderr> (NOTSET)>]
LOGGERS AFTER
[<_StderrHandler <stderr> (WARNING)>, <StreamHandler <stderr> (NOTSET)>]



python3 test/test_truncating.py


LOGGERS BEFORE
[<_StderrHandler <stderr> (WARNING)>]
LOGGERS AFTER
[<_StderrHandler <stderr> (WARNING)>]
Traceback (most recent call last):
  File "test/test_truncating.py", line 12, in <module>
    div()
    [36m-> <function ...[m
  File "test/test_truncating.py", line 9, in div
    [33;1mreturn[m [31m1[m / var
    [36m           -> '999999999...[m
TypeError: unsupported operand type(s) for /: 'int' and 'str'



python3 test/test_truncating_disabled.py


LOGGERS BEFORE
[<_StderrHandler <stderr> (WARNING)>]
LOGGERS AFTER
[<_StderrHandler <stderr> (WARNING)>]
Traceback (most recent call last):
  File "test/test_truncating_disabled.py", line 12, in <module>
    div()
    [36m-> <function div at 0xDEADBEEF>[m
  File "test/test_truncating_disabled.py", line 9, in div
    [33;1mreturn[m [31m1[m / var
    [36m           -> '999999999999999999999999999999999999999999999999999999999999999999999999999999999999999999999999999999999999999999999999999999999999999999999999999999'[m
TypeError: unsupported operand type(s) for /: 'int' and 'str'



python3 test/test_indentation_error.py


LOGGERS BEFORE
[<_StderrHandler <stderr> (WARNING)>]
LOGGERS AFTER
[<_StderrHandler <stderr> (WARNING)>]
Traceback (most recent call last):
  File "test/test_indentation_error.py", line 13, in <module>
    [35;1mexec[m(code)
    [36m     -> '\nif True:\n    a = 5\n        print("foobar")  #intentional faulty indentation here.\n    b = 7\n'[m
File "<string>", line 4
    print("foobar")  #intentional faulty indentation here.
    ^
IndentationError: unexpected indent



python3 test/test_syntax_error.py


LOGGERS BEFORE
[<_StderrHandler <stderr> (WARNING)>]
LOGGERS AFTER
[<_StderrHandler <stderr> (WARNING)>]
Traceback (most recent call last):
  File "test/test_syntax_error.py", line 12, in <module>
    [35;1mexec[m(code)
    [36m     -> '\nif True:\n    a = 5\n    b = 7 *\n'[m
File "<string>", line 4
    b = 7 *
          ^
SyntaxError: invalid syntax



python3 test/test_without_colors.py


LOGGERS BEFORE
[<_StderrHandler <stderr> (WARNING)>]
LOGGERS AFTER
[<_StderrHandler <stderr> (WARNING)>]
LOGGERS BEFORE
[<_StderrHandler <stderr> (WARNING)>, <FileHandler /mnt/f/funds/better-exception/example.log (NOTSET)>]
LOGGERS AFTER
[<_StderrHandler <stderr> (WARNING)>]



python3 test/test_chaining.py


LOGGERS BEFORE
[<_StderrHandler <stderr> (WARNING)>]
LOGGERS AFTER
[<_StderrHandler <stderr> (WARNING)>]
Traceback (most recent call last):
  File "test/test_chaining.py", line 11, in cause
    div(x, y)
    [36m|   |  -> 0[m
    [36m|   -> 1[m
    [36m-> <function div at 0xDEADBEEF>[m
  File "test/test_chaining.py", line 7, in div
    x / y
    [36m|   -> 0[m
    [36m-> 1[m
ZeroDivisionError: division by zero

During handling of the above exception, another exception occurred:

Traceback (most recent call last):
  File "test/test_chaining.py", line 17, in context
    cause(x, y)
    [36m|     |  -> 0[m
    [36m|     -> 1[m
    [36m-> <function cause at 0xDEADBEEF>[m
  File "test/test_chaining.py", line 13, in cause
    [33;1mraise[m [35;1mValueError[m([31m'Division error'[m)
ValueError: Division error

The above exception was the direct cause of the following exception:

Traceback (most recent call last):
  File "test/test_chaining.py", line 21, in <module>
    context([31m1[m, [31m0[m)
    [36m-> <function context at 0xDEADBEEF>[m
  File "test/test_chaining.py", line 19, in context
    [33;1mraise[m [35;1mValueError[m([31m'Cause error'[m) from e
ValueError: Cause error



